<mujoco model="pucks">
    <compiler inertiafromgeom="true" angle="radian" coordinate="local"/>
    <custom>
        <numeric name="frame_skip" data="1"/>
    </custom>
    <option timestep="0.001" gravity="0 0 0" iterations="20" integrator="Euler"/>

    <default>
        <!-- <joint armature='0.04' damping="1" limited="true"/> -->
        <geom friction="0. 0. 0."/>
    </default>

    <worldbody>
        <light diffuse=".5 .5 .5" pos="0 0 3" dir="0 0 -1"/>
        <geom type="plane" pos="0 0.5 -0.125" size="2 2 0.1" condim="3" friction="0.1 0.005 0.0001"/>
        
        <body name="object1" pos="0 0.2 -0.1">
            <geom size="0.15 0.02" type="cylinder" condim="3" name="object1geom" friction="0.1 0.005 0.0001" rgba="1 0 1 1" mass="2"/>
            <site name="object1site" pos="0 0 0" size="0.02 0.02 0.02" rgba="1 0 0 1" type="sphere"/>
            <joint name="obj1_slidex" type="slide" axis="1 0 0" />
            <joint name="obj1_slidey" type="slide" axis="0 1 0" />
        </body>

        <body name="object2" pos="0.5 0 -0.1">
            <geom size="0.15 0.02" type="cylinder" condim="3" name="object2geom" friction="0.1 0.005 0.0001" rgba="1 1 0 1" mass="2"/>
            <site name="object2site" pos="0 0 0" size="0.02 0.02 0.02" rgba="1 0 0 1" type="sphere"/>
            <joint name="obj2_slidex" type="slide" axis="1 0 0" />
            <joint name="obj2_slidey" type="slide" axis="0 1 0" />
        </body>
    </worldbody>

    
    <actuator>
        <motor joint="obj1_slidex" ctrlrange="-1 1" ctrllimited="true"/>
        <motor joint="obj2_slidex" ctrlrange="-1 1" ctrllimited="true"/>

        <motor joint="obj1_slidey" ctrlrange="-1 1" ctrllimited="true"/>
        <motor joint="obj2_slidey" ctrlrange="-1 1" ctrllimited="true"/>
    </actuator>
</mujoco>